Workbook

Sheet T20M6
A1: Sr. No. | B1: SCREEN_ID | C1: REQUIREMENT_ID | D1: KPIT_TC_ID | E1: Name | F1: Objective | G1: Precondition | H1: Test Script (Step-by-Step) - Step | I1: Test Script (Step-by-Step) - Test Data | J1: Test Script (Step-by-Step) - Expected Result | K1: FEATURE_1 | L1: REFERENCE_DOC | M1: Labels | N1: ANDROID_VER | O1: VEHICLE_MODEL | P1: REGION | Q1: VARIANT_CODE | R1: TEST_LEVEL | S1: TEST_TYPE | T1: HW_REQUIRED | U1: SRL_VERSION | V1: SUB_ID | W1: Status | X1: Priority | Y1: Owner | Z1: Folder | AA1: Vehicle model required for Execution e.g. 30AA Q | AB1: TC creator | AC1: L1 Review by | AD1: L1 Review Comments | AE1: TC Status | AF1: L2 Review by | AG1: L2 Review Comments | AH1: TC Status | AI1: L3 Review by | AJ1: L3 Review Comments | AK1: TC Status | AL1: Remarks | AM1: Execution feasibility Result (Pass/Fail) | AN1: Execution Model | AO1: Execution Region | AP1: Executed by | AQ1: Execution owner
A2: 1 | B2: ー | C2: SR-990705-MCS-04 | D2: KPIT_VRNT_PJ02FEA10-504_7882 | E2: [SWT][KPIT_VRNT_PJ02FEA10-504_7882][System UI] | F2: To verify MCS Bar is displayed on the right side when vehicle has right hand side steering while ICB is flashed with T20M6 variant code | G2: 1. IGN is ON and ICB is up and Ready 2. ICB is flashed with T20M6 variant code 3. ICB language is set to "English" (UK-English) 4. Home screen is active | H2: 1. Observe MCS Bar | J2: After step 1, MCS Bar should be displayed on right side | K2: System UI | L2: Document Name: FCP_management_table_14-8155-s34-dev.xlsx Version : 215512 Section: Sheet/T20T/HANDLE | M2: SWT_PJ, R1418 | N2: A14 | O2: T20T | P2: MA | Q2: T20M6 | R2: SWT1-2 | S2: Variant Test | T2: ー | U2: R1418 | V2: ー | W2: Draft | X2: Normal | Y2: JIRAUSER25009 | Z2: /A14/FCP Validation TCs/T20T/System UI/Variant Test | AB2: Shivani | AC2: Ankush | AD2: No review comment | AE2: Finalized | AF2: Pravin | AG2: No review comment | AH2: Finalized | AM2: Pass | AQ2: Shivani
A3: 2 | B3: ー | C3: SR-080300-PowerFlow-01 | D3: KPIT_VRNT_PJ02FEA10-504_7883 | E3: [SWT][KPIT_VRNT_PJ02FEA10-504_7883][PowerFlow] | F3: To verify "Power Flow" app is displayed on Home and All Apps screen while ICB is flashed with T20M6 variant code | G3: 1. IGN is ON and ICB is up and Ready 2. ICB is flashed with T20M6 variant code 3. ICB language is set to "English" (UK-English) 4. Home screen is active | H3: 1. Observe Home screen | J3: After step 1, "Power Flow" app should be displayed on Home screen | K3: PowerFlow | L3: Document Name: FCP_management_table_14-8155-s34-dev.xlsx Version : 215512 Section: Sheet/T20T/ENGTYPE | M3: SWT_PJ, R1418 | N3: A14 | O3: T20T | P3: MA | Q3: T20M6 | R3: SWT1-2 | S3: Variant Test | T3: ー | U3: R1418 | V3: ー | W3: Draft | X3: Normal | Y3: JIRAUSER25009 | Z3: /A14/FCP Validation TCs/T20T/PowerFlow/Variant Test | AB3: Shivani | AC3: Ankush | AD3: 3. Step and expected result is missing for all app | AE3: Rework Review | AF3: Pravin | AG3: No review comment | AH3: Finalized | AM3: Pass | AQ3: Shivani
H4: 2. Go to "All Apps" | J4: After step 2, "Power Flow" app should be displayed in All Apps
A5: 3 | B5: ー | C5: SR-010200-Radio-01 | D5: KPIT_VRNT_PJ02FEA10-504_7884 | E5: [SWT][KPIT_VRNT_PJ02FEA10-504_7884][Analog Radio] | F5: To verify the Frequency Range (87.5MHz-108.0MHz) of FM when "SEEK" operation is performed on FM screen while ICB is flashed with T20M6 variant code | G5: 1. IGN is ON and ICB is up and Ready 2. ICB is flashed with T20M6 variant code 3. ICB language is set to "English" (UK-English) 4. Tuner Simulator is connected to ICB 5. FM is tuned to 87.5MHz on tuner simulator 6. FM screen is active | H5: 1. Set 108.0MHz frequency by entering numbers (0-9) on FM Tune screen | K5: Analog Radio | L5: Document Name: FCP_management_table_14-8155-s34-dev.xlsx Version : 215512 Section: Sheet/T20T/BAND | M5: SWT_PJ, R1418 | N5: A14 | O5: T20T | P5: MA | Q5: T20M6 | R5: SWT1-2 | S5: Variant Test | T5: Tuner Simulator | U5: R1418 | V5: ー | W5: Draft | X5: Normal | Y5: JIRAUSER25009 | Z5: /A14/FCP Validation TCs/T20T/Analog Radio/Variant Test | AB5: Shivani | AC5: Ankush | AD5: 3. Expected result is missing for step 3 4. Required HW missing in HW field | AE5: Rework Review | AF5: Pravin | AG5: No review comment | AH5: Finalized | AJ5: ok | AM5: Pass | AQ5: Niharika
H6: 2. Select "Enter"
H7: 3. Select SEEK UP | J7: After step 3, 87.5MHz should be displayed on FM screen
H8: 4. Tune FM to 108.0MHz on tuner simulator
H9: 5. Select "Tune" on FM screen
H10: 6. Set 87.5MHz frequency by entering numbers (0-9) on FM Tune screen
H11: 7. Select "Enter"
H12: 8. Select SEEK DOWN | J12: After step 8, 108.0MHz should be displayed on FM screen
A13: 4 | B13: ー | C13: SR-010200-Radio-10 | D13: KPIT_VRNT_PJ02FEA10-504_7885 | E13: [SWT][KPIT_VRNT_PJ02FEA10-504_7885][Analog Radio] | F13: To verify the Frequency Range (87.5MHz-108.0MHz) of FM when "Tune" operation is performed on FM Tune Screen while ICB is flashed with T20M6 variant code | G13: 1. IGN is ON and ICB is up and Ready 2. ICB is flashed with T20M6 variant code 3. ICB language is set to "English" (UK-English) 4. Tuner Simulator is connected to ICB 5. FM is tuned to 108.0MHz on Tuner Simulator 6. FM screen is active | H13: 1. Select "Tune" | K13: Analog Radio | L13: Document Name: FCP_management_table_14-8155-s34-dev.xlsx Version : 215512 Section: Sheet/T20T/BAND | M13: SWT_PJ, R1418 | N13: A14 | O13: T20T | P13: MA | Q13: T20M6 | R13: SWT1-2 | S13: Variant Test | T13: Tuner Simulator | U13: R1418 | V13: ー | W13: Draft | X13: Normal | Y13: JIRAUSER25009 | Z13: /A14/FCP Validation TCs/T20T/Analog Radio/Variant Test | AB13: Shivani | AC13: Ankush | AD13: 4. Required HW missing in HW field | AE13: Rework Review | AF13: Pravin | AG13: No review comment | AH13: Finalized | AJ13: ok | AM13: Pass | AQ13: Niharika
H14: 2. Select TUNE UP | J14: After step 2, 87.5MHz should be displayed on FM Tune Screen
H15: 3. Select TUNE DOWN | J15: After step 3, 108.0MHz should be displayed on FM Tune Screen
A16: 5 | B16: ー | C16: SR-010200-Radio-01 | D16: KPIT_VRNT_PJ02FEA10-504_7886 | E16: [SWT][KPIT_VRNT_PJ02FEA10-504_7886][Analog Radio] | F16: To verify the Frequency increase/decrease by 100kHz when perform Tune up/Tune Down operation on FM Tune screen while ICB is flashed with T20M6 variant code | G16: 1. IGN is ON and ICB is up and Ready 2. ICB is flashed with T20M6 variant code 3. ICB language is set to "English" (UK-English) 4. Tuner Simulator is connected to ICB 5. FM is tuned to 90.0MHz 6. FM screen is active | H16: 1. Select "Tune" | K16: Analog Radio | L16: Document Name: FCP_management_table_14-8155-s34-dev.xlsx Version : 215512 Section: Sheet/T20T/BAND | M16: SWT_PJ, R1418 | N16: A14 | O16: T20T | P16: MA | Q16: T20M6 | R16: SWT1-2 | S16: Variant Test | T16: Tuner Simulator | U16: R1418 | V16: ー | W16: Draft | X16: Normal | Y16: JIRAUSER25009 | Z16: /A14/FCP Validation TCs/T20T/Analog Radio/Variant Test | AB16: Shivani | AC16: Ankush | AD16: 4. Required HW missing in HW field | AE16: Rework Review | AF16: Pravin | AG16: No review comment | AH16: Finalized | AJ16: ok | AM16: Pass | AQ16: Niharika
H17: 2. Select TUNE DOWN | J17: After step 2, Frequency range should be decreased by 100kHz and 89.9MHz is displayed on FM Tune screen
H18: 3. Select TUNE UP | J18: After step 3, Frequency range should be increased by 100kHz and 90MHz is displayed on FM Tune screen
A19: 6 | B19: ー | C19: SR-010200-Radio-01 | D19: KPIT_VRNT_PJ02FEA10-504_7887 | E19: [SWT][KPIT_VRNT_PJ02FEA10-504_7887][Analog Radio] | F19: To verify Default preset initial values is displayed as 87.5MHz, 98.1MHz, 108.0MHz on FM screen while ICB is flashed with T20M6 variant code | G19: 1. IGN is ON and ICB is up and Ready 2. ICB is flashed with T20M6 variant code 3. ICB is started for the first time after SW flashing 4. ICB language is set to "English" (UK-English) 5. Home screen is active | H19: 1. Go to "FM" | K19: Analog Radio | L19: Document Name: FCP_management_table_14-8155-s34-dev.xlsx Version : 215512 Section: Sheet/T20T/BAND | M19: SWT_PJ, R1418 | N19: A14 | O19: T20T | P19: MA | Q19: T20M6 | R19: SWT1-2 | S19: Variant Test | T19: ー | U19: R1418 | V19: ー | W19: Draft | X19: Normal | Y19: JIRAUSER25009 | Z19: /A14/FCP Validation TCs/T20T/Analog Radio/Variant Test | AB19: Shivani | AC19: Ankush | AD19: No review comment | AE19: Finalized | AF19: Pravin | AG19: No review comment | AH19: Finalized | AM19: Pass | AQ19: Shivani
H20: 2. Observe the first three presets values | J20: After step 2, First three presets initial values should be displayed as 87.5MHz, 98.1MHz,108.0MHz on FM screen
A21: 7 | B21: ー | C21: SR-010200-Radio-01 | D21: KPIT_VRNT_PJ02FEA10-504_7888 | E21: [SWT][KPIT_VRNT_PJ02FEA10-504_7888][Analog Radio] | F21: To verify the Frequency Range (531kHz-1602kHz) of AM is displayed when AM "SEEK" operation is performed while AM playback is in Progress and ICB is flashed with T20M6 variant code | G21: 1. IGN is ON and ICB is up and Ready 2. ICB is flashed with T20M6 variant code 3. ICB language is set to "English" (UK-English) 4. Tuner Simulator is connected to ICB 5. AM is tuned to 531kHz on Tuner Simulator 6. AM Tune screen is active | H21: 1. Set 1602kHz frequency by entering numbers (0-9) on AM Tune screen | K21: Analog Radio | L21: Document Name: FCP_management_table_14-8155-s34-dev.xlsx Version : 215512 Section: Sheet/T20T/BAND | M21: SWT_PJ, R1418 | N21: A14 | O21: T20T | P21: MA | Q21: T20M6 | R21: SWT1-2 | S21: Variant Test | T21: Tuner Simulator | U21: R1418 | V21: ー | W21: Draft | X21: Normal | Y21: JIRAUSER25009 | Z21: /A14/FCP Validation TCs/T20T/Analog Radio/Variant Test | AB21: Shivani | AC21: Ankush | AD21: 4. Required HW missing in HW field | AE21: Rework Review | AF21: Pravin | AG21: No review comment | AH21: Finalized | AJ21: ok | AM21: Hold | AQ21: Niharika
H22: 2. Select "Enter"
H23: 3. Select SEEK UP | J23: After step 3, 531kHz should be displayed on AM screen
H24: 4. Tune AM to 1602kHz on Tuner simulator
H25: 5. Select "Tune" on AM screen
H26: 6. Set 531kHz frequency by entering numbers (0-9) on AM Tune screen
H27: 7. Select "Enter"
H28: 8. Select SEEK DOWN | J28: After step 8, 1602kHz should be displayed on AM Screen
A29: 8 | B29: ー | C29: SR-010200-Radio-10 | D29: KPIT_VRNT_PJ02FEA10-504_7889 | E29: [SWT][KPIT_VRNT_PJ02FEA10-504_7889][Analog Radio] | F29: To verify the Frequency Range (531kHz-1602kHz) of AM is displayed when AM "Tune" operation is performed while AM playback is in Progress and ICB is flashed with T20M6 variant code | G29: 1. IGN is ON and ICB is up and Ready 2. ICB is flashed with T20M6 variant code 3. ICB language is set to "English" (UK-English) 4. Tuner Simulator is connected to ICB 5. AM is tuned to 1602kHz on Tuner Simulator 6. AM screen is active | H29: 1. Select "Tune" | K29: Analog Radio | L29: Document Name: FCP_management_table_14-8155-s34-dev.xlsx Version : 215512 Section: Sheet/T20T/BAND | M29: SWT_PJ, R1418 | N29: A14 | O29: T20T | P29: MA | Q29: T20M6 | R29: SWT1-2 | S29: Variant Test | T29: Tuner Simulator | U29: R1418 | V29: ー | W29: Draft | X29: Normal | Y29: JIRAUSER25009 | Z29: /A14/FCP Validation TCs/T20T/Analog Radio/Variant Test | AB29: Shivani | AC29: Ankush | AD29: 4. Required HW missing in HW field | AE29: Rework Review | AF29: Pravin | AG29: No review comment | AH29: Finalized | AJ29: ok | AM29: Hold | AQ29: Niharika
H30: 2. Select TUNE UP | J30: After step 2, 531kHz should be displayed on AM Screen
H31: 3. Select TUNE DOWN | J31: After step 3, 1602kHz should be displayed on AM Screen
A32: 9 | B32: ー | C32: SR-010200-Radio-10 | D32: KPIT_VRNT_PJ02FEA10-504_7890 | E32: [SWT][KPIT_VRNT_PJ02FEA10-504_7890][Analog Radio] | F32: To verify the Frequency Step increase/decrease by 9kHz of AM when AM playback is in Progress while ICB is flashed with T20M6 variant code | G32: 1. IGN is ON and ICB is up and Ready 2. ICB is flashed with T20M6 variant code 3. ICB language is set to "English" (UK-English) 4. Tuner Simulator is connected to ICB 5. AM is tuned to 990kHz on Tuner Simulator 6. AM screen is active | H32: 1. Select "Tune" | K32: Analog Radio | L32: Document Name: FCP_management_table_14-8155-s34-dev.xlsx Version : 215512 Section: Sheet/T20T/BAND | M32: SWT_PJ, R1418 | N32: A14 | O32: T20T | P32: MA | Q32: T20M6 | R32: SWT1-2 | S32: Variant Test | T32: Tuner Simulator | U32: R1418 | V32: ー | W32: Draft | X32: Normal | Y32: JIRAUSER25009 | Z32: /A14/FCP Validation TCs/T20T/Analog Radio/Variant Test | AB32: Shivani | AC32: Ankush | AD32: 4. Required HW missing in HW field | AE32: Rework Review | AF32: Pravin | AG32: No review comment | AH32: Finalized | AJ32: ok | AM32: Hold | AQ32: Niharika
H33: 2. Select TUNE DOWN | J33: After step 2, Frequency range should be decreased by 9kHz steps and 981kHz should be displayed on AM Tune screen
H34: 3. Select TUNE UP | J34: After step 3, Frequency range should be increased by 9kHz steps and 990kHz should be displayed on AM Tune screen
A35: 10 | B35: ー | C35: SR-010200-Radio-01 | D35: KPIT_VRNT_PJ02FEA10-504_7891 | E35: [SWT][KPIT_VRNT_PJ02FEA10-504_7891][Analog Radio] | F35: To verify first three preset initial value is displayed as 531kHz, 999kHz, 1602kHz on AM screen while ICB is flashed with T20M6 variant code | G35: 1. IGN is ON and ICB is up and Ready 2. ICB is flashed with T20M6 variant code 3. ICB is started for the first time after SW flashing 4. ICB language is set to "English" (UK-English) 5. Home screen is active | H35: 1. Go to "AM" | K35: Analog Radio | L35: Document Name: FCP_management_table_14-8155-s34-dev.xlsx Version : 215512 Section: Sheet/T20T/BAND | M35: SWT_PJ, R1418 | N35: A14 | O35: T20T | P35: MA | Q35: T20M6 | R35: SWT1-2 | S35: Variant Test | T35: ー | U35: R1418 | V35: ー | W35: Draft | X35: Normal | Y35: JIRAUSER25009 | Z35: /A14/FCP Validation TCs/T20T/Analog Radio/Variant Test | AB35: Shivani | AC35: Ankush | AD35: No review comment | AE35: Finalized | AF35: Pravin | AG35: No review comment | AH35: Finalized | AM35: Hold | AQ35: Niharika
H36: 2. Observe the first three presets values | J36: After step 2, AM first three presets initial values should be displayed as 531kHz, 999kHz, 1602kHz on AM screen
A37: 11 | B37: ー | C37: SR-010200-Radio-11 | D37: KPIT_VRNT_PJ02FEA10-504_7892 | E37: [SWT][KPIT_VRNT_PJ02FEA10-504_7892][Analog Radio] | F37: To verify AM frequency is tuned down continuously when long pressed on TUNE DOWN from AM Tune Keyboard screen while ICB is flashed with T20M6 variant code | G37: 1. IGN is ON and ICB is up and Ready 2. ICB is flashed with T20M6 variant code 3. ICB language is set to "English" (UK-English) 4. Input area is empty on Tune Keyboard 5. AM Tune Keyboard screen is active | H37: 1. Long press TUNE DOWN | J37: After step 1, AM frequency should be tuned DOWN continuously when long pressed on TUNE DOWN from AM Tune Keyboard screen | K37: Analog Radio | L37: Document Name: FCP_management_table_14-8155-s34-dev.xlsx Version : 215512 Section: Sheet/T20T/BAND | M37: SWT_PJ, R1418 | N37: A14 | O37: T20T | P37: MA | Q37: T20M6 | R37: SWT1-2 | S37: Variant Test | T37: ー | U37: R1418 | V37: ー | W37: Draft | X37: Normal | Y37: JIRAUSER25009 | Z37: /A14/FCP Validation TCs/T20T/Analog Radio/Variant Test | AB37: Shivani | AC37: Ankush | AD37: No review comment | AE37: Finalized | AF37: Pravin | AG37: No review comment | AH37: Finalized | AM37: Hold | AQ37: Niharika
A38: 12 | B38: ー | C38: SR-010200-Radio-11 | D38: KPIT_VRNT_PJ02FEA10-504_7893 | E38: [SWT][KPIT_VRNT_PJ02FEA10-504_7893][Analog Radio] | F38: To verify AM frequency is tuned up continuously when long pressed on TUNE UP from AM Tune Keyboard screen while ICB is flashed with T20M6 variant code | G38: 1. IGN is ON and ICB is up and Ready 2. ICB is flashed with T20M6 variant code 3. ICB language is set to "English" (UK-English) 4. Input area is empty on Tune Keyboard 5. AM Tune Keyboard screen is active | H38: 1. Long press TUNE UP | J38: After step 1, AM frequency should be tuned UP continuously when long pressed on TUNE UP from AM Tune Keyboard screen | K38: Analog Radio | L38: Document Name: FCP_management_table_14-8155-s34-dev.xlsx Version : 215512 Section: Sheet/T20T/BAND | M38: SWT_PJ, R1418 | N38: A14 | O38: T20T | P38: MA | Q38: T20M6 | R38: SWT1-2 | S38: Variant Test | T38: ー | U38: R1418 | V38: ー | W38: Draft | X38: Normal | Y38: JIRAUSER25009 | Z38: /A14/FCP Validation TCs/T20T/Analog Radio/Variant Test | AB38: Shivani | AC38: Ankush | AD38: No review comment | AE38: Finalized | AF38: Pravin | AG38: No review comment | AH38: Finalized | AM38: Hold | AQ38: Niharika
A39: 13 | B39: ー | C39: SR-010200-Radio-03 | D39: KPIT_VRNT_PJ02FEA10-504_7894 | E39: [SWT][KPIT_VRNT_PJ02FEA10-504_7894][Analog Radio] | F39: To verify FM audio is audible from speakers when FM is selected from "Home" screen while ICB is flashed with T20M6 variant code | G39: 1. IGN is ON and ICB is up and Ready 2. ICB is flashed with T20M6 variant code 3. ICB language is set to "English" (UK-English) 4. Tuner Simulator is connected to ICB 5. FM is tuned to a valid station and audio is audible from speaker 6. Home screen is active | H39: 1. Go to "FM" | J39: After step 1, "FM" audio should be audible from speakers | K39: Analog Radio | L39: Document Name: FCP_management_table_14-8155-s34-dev.xlsx Version : 215512 Section: Sheet/T20T/BAND | M39: SWT_PJ, R1418 | N39: A14 | O39: T20T | P39: MA | Q39: T20M6 | R39: SWT1-2 | S39: Variant Test | T39: Tuner Simulator | U39: R1418 | V39: ー | W39: Draft | X39: Normal | Y39: JIRAUSER25009 | Z39: /A14/FCP Validation TCs/T20T/Analog Radio/Variant Test | AB39: Shivani | AC39: Ankush | AD39: 4. Required HW missing in HW field | AE39: Rework Review | AF39: Pravin | AG39: No review comment | AH39: Finalized | AM39: Pass | AQ39: Niharika
A40: 14 | B40: ー | C40: SR-010200-Radio-03 | D40: KPIT_VRNT_PJ02FEA10-504_7895 | E40: [SWT][KPIT_VRNT_PJ02FEA10-504_7895][Analog Radio] | F40: To verify FM audio is audible from speakers when FM icon is selected from Audio source list screen while ICB is flashed with T20M6 variant code | G40: 1. IGN is ON and ICB is up and Ready 2. ICB is flashed with T20M6 variant code 3. ICB language is set to "English" (UK-English) 4. Tuner Simulator is connected to ICB 5. FM is tuned to a valid station and audio is audible from speaker 6. AM Screen is active | H40: 1. Select "AM" | K40: Analog Radio | L40: Document Name: FCP_management_table_14-8155-s34-dev.xlsx Version : 215512 Section: Sheet/T20T/BAND | M40: SWT_PJ, R1418 | N40: A14 | O40: T20T | P40: MA | Q40: T20M6 | R40: SWT1-2 | S40: Variant Test | T40: Tuner Simulator | U40: R1418 | V40: ー | W40: Draft | X40: Normal | Y40: JIRAUSER25009 | Z40: /A14/FCP Validation TCs/T20T/Analog Radio/Variant Test | AB40: Shivani | AC40: Ankush | AD40: 4. Required HW missing in HW field | AE40: Rework Review | AF40: Pravin | AG40: No review comment | AH40: Finalized | AM40: Hold | AQ40: Niharika
...

Sheet Sheet1
B2: 1 | C2: KPIT_VRNT_PJ02FEA10-504_7882 | D2: =VLOOKUP(B2,T20M6!A:K,12,2) -> #REF! | E2: [SWT] | F2: [SWT][KPIT_VRNT_PJ02FEA10-504_7882][System UI]
B3: 2 | C3: KPIT_VRNT_PJ02FEA10-504_7883 | D3: =VLOOKUP(B3,T20M6!A:K,12,2) -> #REF! | E3: [SWT] | F3: [SWT][KPIT_VRNT_PJ02FEA10-504_7883][PowerFlow]
B4: 3 | C4: KPIT_VRNT_PJ02FEA10-504_7884 | D4: =VLOOKUP(B4,T20M6!A:K,12,2) -> #REF! | E4: [SWT] | F4: [SWT][KPIT_VRNT_PJ02FEA10-504_7884][Analog Radio]
B5: 4 | C5: KPIT_VRNT_PJ02FEA10-504_7885 | D5: =VLOOKUP(B5,T20M6!A:K,12,2) -> #REF! | E5: [SWT] | F5: [SWT][KPIT_VRNT_PJ02FEA10-504_7885][Analog Radio]
B6: 5 | C6: KPIT_VRNT_PJ02FEA10-504_7886 | D6: =VLOOKUP(B6,T20M6!A:K,12,2) -> #REF! | E6: [SWT] | F6: [SWT][KPIT_VRNT_PJ02FEA10-504_7886][Analog Radio]
B7: 6 | C7: KPIT_VRNT_PJ02FEA10-504_7887 | D7: =VLOOKUP(B7,T20M6!A:K,12,2) -> #REF! | E7: [SWT] | F7: [SWT][KPIT_VRNT_PJ02FEA10-504_7887][Analog Radio]
B8: 7 | C8: KPIT_VRNT_PJ02FEA10-504_7888 | D8: =VLOOKUP(B8,T20M6!A:K,12,2) -> #REF! | E8: [SWT] | F8: [SWT][KPIT_VRNT_PJ02FEA10-504_7888][Analog Radio]
B9: 8 | C9: KPIT_VRNT_PJ02FEA10-504_7889 | D9: =VLOOKUP(B9,T20M6!A:K,12,2) -> #REF! | E9: [SWT] | F9: [SWT][KPIT_VRNT_PJ02FEA10-504_7889][Analog Radio]
B10: 9 | C10: KPIT_VRNT_PJ02FEA10-504_7890 | D10: =VLOOKUP(B10,T20M6!A:K,12,2) -> #REF! | E10: [SWT] | F10: [SWT][KPIT_VRNT_PJ02FEA10-504_7890][Analog Radio]
B11: 10 | C11: KPIT_VRNT_PJ02FEA10-504_7891 | D11: =VLOOKUP(B11,T20M6!A:K,12,2) -> #REF! | E11: [SWT] | F11: [SWT][KPIT_VRNT_PJ02FEA10-504_7891][Analog Radio]
B12: 11 | C12: KPIT_VRNT_PJ02FEA10-504_7892 | D12: =VLOOKUP(B12,T20M6!A:K,12,2) -> #REF! | E12: [SWT] | F12: [SWT][KPIT_VRNT_PJ02FEA10-504_7892][Analog Radio]
B13: 12 | C13: KPIT_VRNT_PJ02FEA10-504_7893 | D13: =VLOOKUP(B13,T20M6!A:K,12,2) -> #REF! | E13: [SWT] | F13: [SWT][KPIT_VRNT_PJ02FEA10-504_7893][Analog Radio]
... B140: 139 | C140: KPIT_VRNT_PJ02FEA10-504_8020 | D140: =VLOOKUP(B140,T20M6!A:K,12,2) -> #REF! | E140: [SWT] | F140: [SWT][KPIT_VRNT_PJ02FEA10-504_8020][ー]

Sheet Tracebility
C2: T20Y6(R1) | D2: T20Y7(R1) | E2: T20Y8(R1) | F2: T20M6(S1) MA Region | H2: TC Created
A3: HANDLE | B3: FCP_H_CAR_HANDLE_E | C3: LEFT | D3: LEFT | E3: LEFT | F3: RIGHT | G3: Execute | H3: Yes | J3: =_xlfn.CONCAT(B3,"=",F3) -> FCP_H_CAR_HANDLE_E=RIGHT
A4: ENGTYPE | B4: FCP_H_CAR_ENGTYPE_E | C4: GAS | D4: GAS | E4: GAS | F4: FHEV | G4: Execute | H4: Yes | J4: =_xlfn.CONCAT(B4,"=",F4) -> FCP_H_CAR_ENGTYPE_E=FHEV
A5: BAND | B5: FCP_H_RADIO_BAND_E | C5: GENERAL | D5: GENERAL | E5: GENERAL | F5: GENERAL | G5: Execute | H5: Yes | J5: =_xlfn.CONCAT(B5,"=",F5) -> FCP_H_RADIO_BAND_E=GENERAL
A6: DATA | B6: FCP_H_RADIO_DATA_E | C6: RDS_OFF | D6: RDS_OFF | E6: RDS_OFF | F6: NONE | G6: Execute | H6: Yes | J6: =_xlfn.CONCAT(B6,"=",F6) -> FCP_H_RADIO_DATA_E=NONE
A7: DIGITAL | B7: FCP_H_RADIO_DIGITAL_E | C7: DAB_UAE | D7: DAB_UAE | E7: DAB_UAE | F7: NONE | G7: Execute | H7: Yes | J7: =_xlfn.CONCAT(B7,"=",F7) -> FCP_H_RADIO_DIGITAL_E=NONE
A8: SXM | B8: FCP_H_RADIO_SXM_E | C8: NONE | D8: NONE | E8: NONE | F8: NONE | G8: Design Assurance | H8: NA | J8: =_xlfn.CONCAT(B8,"=",F8) -> FCP_H_RADIO_SXM_E=NONE
A9: ANTITHEFT | B9: FCP_H_CAR_ANTITHEFT_B | C9: FALSE | D9: FALSE | E9: FALSE | F9: FALSE | G9: Execute | H9: Yes | J9: =_xlfn.CONCAT(B9,"=",F9) -> FCP_H_CAR_ANTITHEFT_B=FALSE
A10: REAR | B10: FCP_H_CAM_REAR_E | C10: NONE | D10: WIDE | E10: WIDE | F10: WIDE | G10: Execute | H10: Yes | J10: =_xlfn.CONCAT(B10,"=",F10) -> FCP_H_CAM_REAR_E=WIDE
A11: LWC | B11: FCP_H_CAM_LWC_E | C11: NONE | D11: NONE | E11: ASSISTANT | F11: ASSISTANT | G11: Execute | H11: Yes | J11: =_xlfn.CONCAT(B11,"=",F11) -> FCP_H_CAM_LWC_E=ASSISTANT
A12: USBPORT | B12: FCP_H_INPUT_USBPORT_IA | C12: {0x024f} | D12: {0x024f} | E12: {0x024f} | F12: {0x024f} | G12: Design Assurance | H12: NA | J12: =_xlfn.CONCAT(B12,"=",F12) -> FCP_H_INPUT_USBPORT_IA={0x024f}
A13: CARPLAYUSB | B13: FCP_H_APL_CARPLAYUSB_B | C13: TRUE | D13: TRUE | E13: TRUE | F13: TRUE | G13: Execute | H13: Yes | J13: =_xlfn.CONCAT(B13,"=",F13) -> FCP_H_APL_CARPLAYUSB_B=TRUE
A14: CARPLAYWIFI2G | B14: FCP_H_APL_CARPLAYWIFI2G_B | C14: FALSE | D14: FALSE | E14: FALSE | F14: FALSE | G14: Execute | H14: Yes | J14: =_xlfn.CONCAT(B14,"=",F14) -> FCP_H_APL_CARPLAYWIFI2G_B=FALSE
A15: CARPLAYWIFI5G | B15: FCP_H_APL_CARPLAYWIFI5G_B | C15: TRUE | D15: TRUE | E15: TRUE | F15: TRUE | G15: Execute | H15: Yes | J15: =_xlfn.CONCAT(B15,"=",F15) -> FCP_H_APL_CARPLAYWIFI5G_B=TRUE
A16: ANDROIDAUTOUSB | B16: FCP_H_GGL_ANDROIDAUTOUSB_B | C16: TRUE | D16: TRUE | E16: TRUE | F16: TRUE | G16: Execute | H16: Yes | J16: =_xlfn.CONCAT(B16,"=",F16) -> FCP_H_GGL_ANDROIDAUTOUSB_B=TRUE
A17: ANDROIDAUTOWIFI5G | B17: FCP_H_GGL_ANDROIDAUTOWIFI5G_B | C17: TRUE | D17: TRUE | E17: TRUE | F17: TRUE | G17: Execute | H17: Yes | J17: =_xlfn.CONCAT(B17,"=",F17) -> FCP_H_GGL_ANDROIDAUTOWIFI5G_B=TRUE
A18: DDP | B18: FCP_H_CAR_DDP_E | C18: ROW | D18: ROW | E18: ROW | F18: ROW | G18: Execute | H18: Yes | J18: =_xlfn.CONCAT(B18,"=",F18) -> FCP_H_CAR_DDP_E=ROW
A19: REMOTE | B19: FCP_H_RADIO_REMOTE_B | C19: FALSE | D19: FALSE | E19: FALSE | F19: FALSE | G19: Execute | H19: ADB Log | J19: =_xlfn.CONCAT(B19,"=",F19) -> FCP_H_RADIO_REMOTE_B=FALSE
A20: SUBW | B20: FCP_H_SOUND_SUBW_B | C20: FALSE | D20: FALSE | E20: FALSE | F20: FALSE | G20: Execute | H20: Yes | J20: =_xlfn.CONCAT(B20,"=",F20) -> FCP_H_SOUND_SUBW_B=FALSE
A21: FADER | B21: FCP_H_SOUND_FADER_B | C21: TRUE | D21: TRUE | E21: TRUE | F21: TRUE | G21: Execute | H21: Yes | J21: =_xlfn.CONCAT(B21,"=",F21) -> FCP_H_SOUND_FADER_B=TRUE
A22: BALANCE | B22: FCP_H_SOUND_BALANCE_B | C22: TRUE | D22: TRUE | E22: TRUE | F22: TRUE | G22: Execute | H22: Yes | J22: =_xlfn.CONCAT(B22,"=",F22) -> FCP_H_SOUND_BALANCE_B=TRUE
A23: AUDIOZONE | B23: FCP_H_SOUND_AUDIOZONE_B | C23: TRUE | D23: TRUE | E23: TRUE | F23: TRUE | G23: Execute | H23: Yes | J23: =_xlfn.CONCAT(B23,"=",F23) -> FCP_H_SOUND_AUDIOZONE_B=TRUE
A24: EXTAMP | B24: FCP_H_SOUND_EXTAMP_B | C24: TRUE | D24: TRUE | E24: TRUE | F24: TRUE | G24: Execute | H24: Yes | J24: =_xlfn.CONCAT(B24,"=",F24) -> FCP_H_SOUND_EXTAMP_B=TRUE
A25: SURROUND | B25: FCP_H_SOUND_SURROUND_E | C25: BOSE_CTRPOINT | D25: BOSE_CTRPOINT | E25: BOSE_CTRPOINT | F25: BOSE_CTRPOINT | G25: Execute | H25: Yes | J25: =_xlfn.CONCAT(B25,"=",F25) -> FCP_H_SOUND_SURROUND_E=BOSE_CTRPOINT
A26: OPENING | B26: FCP_H_STARTUP_OPENING_E | C26: HMARK | D26: HMARK | E26: HMARK | F26: HMARK | G26: Execute | H26: Yes | J26: =_xlfn.CONCAT(B26,"=",F26) -> FCP_H_STARTUP_OPENING_E=HMARK
A27: ETC | B27: FCP_H_V2X_ETC_E | C27: NONE | D27: NONE | E27: NONE | F27: NONE | G27: Execute | H27: Yes | J27: =_xlfn.CONCAT(B27,"=",F27) -> FCP_H_V2X_ETC_E=NONE
A28: MANUFACTURER | B28: FCP_H_APL_MANUFACTURER_S | C28: "HONDA/00_T20Y6" | D28: "HONDA/00_T20Y7" | E28: "HONDA/00_T20Y8" | F28: "HONDA/00_T20M6" | G28: Execute | H28: ADB Log | J28: =_xlfn.CONCAT(B28,"=",F28) -> FCP_H_APL_MANUFACTURER_S="HONDA/00_T20M6"
A29: MY | B29: FCP_H_GGL_MY_I | C29: 2027 | D29: 2027 | E29: 2027 | F29: 2027 | G29: Execute | H29: Yes | J29: =_xlfn.CONCAT(B29,"=",F29) -> FCP_H_GGL_MY_I=2027
A30: MODEL | B30: FCP_H_GGL_MODEL_S | C30: "T20" | D30: "T20" | E30: "T20" | F30: "T20" | G30: Execute | H30: Yes | J30: =_xlfn.CONCAT(B30,"=",F30) -> FCP_H_GGL_MODEL_S="T20"
A31: PROTOCOLPANDORA | B31: FCP_H_EAP_PROTOCOLPANDORA_S | C31: "" | D31: "" | E31: "" | F31: "" | G31: Design Assurance | H31: NA | J31: =_xlfn.CONCAT(B31,"=",F31) -> FCP_H_EAP_PROTOCOLPANDORA_S=""
A32: PROTOCOLLINKMANAGER | B32: FCP_H_EAP_PROTOCOLLINKMANAGER_S | C32: "com.honda.hondalink.hlc" | D32: "com.honda.hondalink.hlc" | E32: "com.honda.hondalink.hlc" | F32: "" | G32: Design Assurance | H32: NA | J32: =_xlfn.CONCAT(B32,"=",F32) -> FCP_H_EAP_PROTOCOLLINKMANAGER_S=""
A33: VE | B33: FCP_H_EAP_VE_B | C33: TRUE | D33: TRUE | E33: TRUE | F33: TRUE | G33: Execute | H33: Yes | J33: =_xlfn.CONCAT(B33,"=",F33) -> FCP_H_EAP_VE_B=TRUE
A34: PANDORA | B34: FCP_H_EAP_PANDORA_B | C34: FALSE | D34: FALSE | E34: FALSE | F34: FALSE | G34: Design Assurance | H34: NA | J34: =_xlfn.CONCAT(B34,"=",F34) -> FCP_H_EAP_PANDORA_B=FALSE
A35: LINKMANAGER | B35: FCP_H_EAP_LINKMANAGER_B | C35: FALSE | D35: FALSE | E35: FALSE | F35: FALSE | G35: Execute | H35: Yes | J35: =_xlfn.CONCAT(B35,"=",F35) -> FCP_H_EAP_LINKMANAGER_B=FALSE
A36: PARAMERFILE | B36: FCP_H_OTHER_PARAMERFILE_S | C36: T20Y6.json | D36: T20Y7.json | E36: T20Y8.json | F36: T20M6.json | G36: Execute | H36: ADB Log | J36: =_xlfn.CONCAT(B36,"=",F36) -> FCP_H_OTHER_PARAMERFILE_S=T20M6.json
A37: ENABLE | B37: FCP_H_DTV_ENABLE_B | C37: FALSE | D37: FALSE | E37: FALSE | F37: FALSE | G37: Execute | H37: Yes | J37: =_xlfn.CONCAT(B37,"=",F37) -> FCP_H_DTV_ENABLE_B=FALSE
A38: AM | B38: FCP_H_RADIO_AM_B | C38: TRUE | D38: TRUE | E38: TRUE | F38: TRUE | G38: Execute | H38: Yes | J38: =_xlfn.CONCAT(B38,"=",F38) -> FCP_H_RADIO_AM_B=TRUE
A39: ACCESSORYMODEL | B39: FCP_H_APL_ACCESSORYMODEL_S | C39: "T20" | D39: "T20" | E39: "T20" | F39: "T20" | G39: Execute | H39: ADB Log | J39: =_xlfn.CONCAT(B39,"=",F39) -> FCP_H_APL_ACCESSORYMODEL_S="T20"
A40: LANG_DEFALUT | B40: FCP_H_LOCALE_LANG_DEFALUT_S | C40: "ar-SA" | D40: "ar-SA" | E40: "ar-SA" | F40: "en-GB" | G40: Execute | H40: Yes | J40: =_xlfn.CONCAT(B40,"=",F40) -> FCP_H_LOCALE_LANG_DEFALUT_S="en-GB"
A41: LANG_SUPPORT | B41: FCP_H_LOCALE_LANG_SUPPORT_SA | C41: {"en-GB","ar-SA"} | D41: {"en-GB","ar-SA"} | E41: {"en-GB","ar-SA"} | F41: {"en-GB","fr-CA","es-MX","zh-Hant-MO","in-ID","th-TH"} | G41: Execute | H41: Yes | J41: =_xlfn.CONCAT(B41,"=",F41) -> FCP_H_LOCALE_LANG_SUPPORT_SA={"en-GB","fr-CA","es-MX","zh-Hant-MO","in-ID","th-TH"}
...

Sheet 30AW
A1: Sr. No. | B1: SCREEN_ID | C1: REQUIREMENT_ID | D1: KPIT_TC_ID | E1: Name | F1: Objective | G1: Precondition | H1: Test Script (Step-by-Step) - Step | I1: Test Script (Step-by-Step) - Test Data | J1: Test Script (Step-by-Step) - Expected Result | K1: FEATURE_1 | L1: REFERENCE_DOC | M1: Labels | N1: ANDROID_VER | O1: VEHICLE_MODEL | P1: REGION | Q1: VARIANT_CODE | R1: TEST_LEVEL | S1: TEST_TYPE | T1: HW_REQUIRED | U1: SRL_VERSION | V1: SUB_ID | W1: Status | X1: Priority | Y1: Owner | Z1: Folder | AA1: Vehicle model required for Execution e.g. 30AA Q | AB1: TC creator | AC1: L1 Review by | AD1: L1 Review Comments | AE1: TC Status | AF1: L2 Review by | AG1: L2 Review Comments | AH1: TC Status | AI1: L3 Review by | AJ1: L3 Review Comments | AK1: TC Status | AL1: Remarks | AM1: Execution feasibility Result (Pass/Fail) | AN1: Execution Model | AO1: Execution Region | AP1: Executed by
A2: 1 | B2: ー | C2: SR-990704-StatusBar-08 | D2: KPIT_VRNT_PJ02FEA10-504_8021 | E2: [SWT][KPIT_VRNT_PJ02FEA10-504_8021][System UI] | F2: To verify TSU Field strength icon is not displayed on Header when ICB is flashed with 30AWA variant code | G2: 1. IGN is ON and ICB is up and Ready 2. ICB is flashed with 30AWA variant code 4. Home screen is active | H2: 1. Observe Header | J2: After step 1, TSU Field strength icon should not be displayed on Header | K2: System UI | L2: Document Name: FCP_management_table_14-8155-s34-dev.xlsx Version : 215512 Section: Sheet/30AW/ENABLEPKG | M2: SWT_PJ, R1418 | N2: A14 | O2: 30AW | P2: KY | Q2: 30AWA | R2: SWT1-2 | S2: Variant Test | T2: ー | U2: R1418 | V2: ー | W2: Draft | X2: Normal | Y2: JIRAUSER22518 | Z2: /A14/FCP Validation TCs/30AW/System UI/Variant Test | AB2: Shivani | AC2: Ankush | AD2: 1. Folder path is incorrect 2. Feature1 is incorrect | AE2: Rework Needed | AM2: Pass | AP2: Niharika
A3: 2 | B3: ー | C3: ー | D3: KPIT_VRNT_PJ02FEA10-504_8022 | E3: [SWT][KPIT_VRNT_PJ02FEA10-504_8022][ー] | F3: To verify the value of "ENABLEPKG" is displayed as {"com.honda.ivi.systemupdate","com.honda.ivi.clockFaces","com.honda.ivi.am"} in ADB logs when ICB is flashed with 30AWC variant code | G3: 1. IGN is ON and ICB is up and Ready 2. ICB is flashed with 30AWC variant code 3. Home screen is active | H3: 1. Go to Settings -> Advanced Settings -> System -> About -> Click on Build Number on 5 times -> Enter developer option password -> Back -> Developer option -> Enable USB Debugging Mode and USB Mode Setting enable | K3: ー | L3: Document Name: FCP_management_table_14-8155-s34-dev.xlsx Version : 215512 Section: Sheet/30AW/ENABLEPKG | M3: SWT_PJ, R1418 | N3: A14 | O3: 30AW | P3: KY | Q3: 30AWC | R3: SWT1-2 | S3: Variant Test | T3: ADB Cable | U3: R1418 | V3: ー | W3: Draft | X3: Normal | Y3: JIRAUSER22518 | Z3: /A14/FCP Validation TCs/30AW/ー/Variant Test | AB3: Shivani | AC3: Ankush | AD3: 1. Folder path is incorrect 2. Feature1 is incorrect | AE3: Rework Needed | AM3: Pass | AP3: Niharika
H4: 2. Go to extracted adb folder and enter command prompt by entering "cmd" in adb folder's path
H5: 3. Enter "adb devices" and check under "List of devices attached"
H6: 4. Enter "adb bugreport"
H7: 5. Extract "bugreport" folder
H8: 6. Open "bugreport" log file
H9: 7. Search for "FCP_H_APPMANAGE_ENABLEPKG_SA" in bugreport log file | J9: After step 1, 7.1 Value of "ENABLEPKG" should be displayed as {"com.honda.ivi.systemupdate","com.honda.ivi.clockFaces","com.honda.ivi.am"} in ADB logs 7.2 "com.honda.ivi.telematicscontrolservice" value should not be displayed in "ENABLEPKG"
A10: 3 | B10: ー | C10: ー | D10: KPIT_VRNT_PJ02FEA10-504_8023 | E10: [SWT][KPIT_VRNT_PJ02FEA10-504_8023][ー] | F10: To verify the value of "ENABLEPKG" is displayed as {"com.honda.ivi.systemupdate","com.honda.ivi.clockFaces","com.honda.ivi.am"} in ADB logs when ICB is flashed with 30AWD variant code | G10: 1. IGN is ON and ICB is up and Ready 2. ICB is flashed with 30AWD variant code 3. Home screen is active | H10: 1. Go to Settings -> Advanced Settings -> System -> About -> Click on Build Number on 5 times -> Enter developer option password -> Back -> Developer option -> Enable USB Debugging Mode and USB Mode Setting enable | K10: ー | L10: Document Name: FCP_management_table_14-8155-s34-dev.xlsx Version : 215512 Section: Sheet/30AW/ENABLEPKG | M10: SWT_PJ, R1418 | N10: A14 | O10: 30AW | P10: KY | Q10: 30AWD | R10: SWT1-2 | S10: Variant Test | T10: ADB Cable | U10: R1418 | V10: ー | W10: Draft | X10: Normal | Y10: JIRAUSER22518 | Z10: /A14/FCP Validation TCs/30AW/ー/Variant Test | AB10: Shivani | AC10: Ankush | AD10: 1. Folder path is incorrect 2. Feature1 is incorrect | AE10: Rework Needed | AM10: Pass | AP10: Niharika
H11: 2. Go to extracted adb folder and enter command prompt by entering "cmd" in adb folder's path
H12: 3. Enter "adb devices" and check under "List of devices attached"
H13: 4. Enter "adb bugreport"
H14: 5. Extract "bugreport" folder
H15: 6. Open "bugreport" log file
H16: 7. Search for "FCP_H_APPMANAGE_ENABLEPKG_SA" in bugreport log file | J16: After step 1, 7.1 Value of "ENABLEPKG" should be displayed as {"com.honda.ivi.systemupdate","com.honda.ivi.clockFaces","com.honda.ivi.am"} in ADB logs 7.2 "com.honda.ivi.telematicscontrolservice" value should not be displayed in "ENABLEPKG"
A17: 4 | B17: ー | C17: ー | D17: KPIT_VRNT_PJ02FEA10-504_8024 | E17: [SWT][KPIT_VRNT_PJ02FEA10-504_8024][ー] | F17: To verify the value of "ENABLEPKG" is displayed as {"com.honda.ivi.systemupdate","com.honda.ivi.clockFaces","com.honda.ivi.am"} in ADB logs when ICB is flashed with 30AXC variant code | G17: 1. IGN is ON and ICB is up and Ready 2. ICB is flashed with 30AXC variant code 3. Home screen is active | H17: 1. Go to Settings -> Advanced Settings -> System -> About -> Click on Build Number on 5 times -> Enter developer option password -> Back -> Developer option -> Enable USB Debugging Mode and USB Mode Setting enable | K17: ー | L17: Document Name: FCP_management_table_14-8155-s34-dev.xlsx Version : 215512 Section: Sheet/30AW/ENABLEPKG | M17: SWT_PJ, R1418 | N17: A14 | O17: 30AW | P17: KY | Q17: 30AXC | R17: SWT1-2 | S17: Variant Test | T17: ADB Cable | U17: R1418 | V17: ー | W17: Draft | X17: Normal | Y17: JIRAUSER22518 | Z17: /A14/FCP Validation TCs/30AW/ー/Variant Test | AB17: Shivani | AC17: Ankush | AD17: 1. Folder path is incorrect 2. Feature1 is incorrect | AE17: Rework Needed | AM17: Pass | AP17: Niharika
H18: 2. Go to extracted adb folder and enter command prompt by entering "cmd" in adb folder's path
H19: 3. Enter "adb devices" and check under "List of devices attached"
H20: 4. Enter "adb bugreport"
H21: 5. Extract "bugreport" folder
H22: 6. Open "bugreport" log file
H23: 7. Search for "FCP_H_APPMANAGE_ENABLEPKG_SA" in bugreport log file | J23: After step 1, 7.1 Value of "ENABLEPKG" should be displayed as {"com.honda.ivi.systemupdate","com.honda.ivi.clockFaces","com.honda.ivi.am"} in ADB logs 7.2 "com.honda.ivi.telematicscontrolservice" value should not be displayed in "ENABLEPKG"
A24: 5 | B24: ー | C24: ー | D24: KPIT_VRNT_PJ02FEA10-504_8025 | E24: [SWT][KPIT_VRNT_PJ02FEA10-504_8025][ー] | F24: To verify the value of "ENABLEPKG" is displayed as {"com.honda.ivi.systemupdate","com.honda.ivi.clockFaces","com.honda.ivi.am"} in ADB logs when ICB is flashed with 30AWM variant code | G24: 1. IGN is ON and ICB is up and Ready 2. ICB is flashed with 30AWM variant code 3. Home screen is active | H24: 1. Go to Settings -> Advanced Settings -> System -> About -> Click on Build Number on 5 times -> Enter developer option password -> Back -> Developer option -> Enable USB Debugging Mode and USB Mode Setting enable | K24: ー | L24: Document Name: FCP_management_table_14-8155-s34-dev.xlsx Version : 215512 Section: Sheet/30AW/ENABLEPKG | M24: SWT_PJ, R1418 | N24: A14 | O24: 30AW | P24: KY | Q24: 30AWM | R24: SWT1-2 | S24: Variant Test | T24: ADB Cable | U24: R1418 | V24: ー | W24: Draft | X24: Normal | Y24: JIRAUSER22518 | Z24: /A14/FCP Validation TCs/30AW/ー/Variant Test | AB24: Shivani | AC24: Ankush | AD24: 1. Folder path is incorrect 2. Feature1 is incorrect | AE24: Rework Needed | AM24: Pass | AP24: Niharika
H25: 2. Go to extracted adb folder and enter command prompt by entering "cmd" in adb folder's path
H26: 3. Enter "adb devices" and check under "List of devices attached"
H27: 4. Enter "adb bugreport"
H28: 5. Extract "bugreport" folder
H29: 6. Open "bugreport" log file
H30: 7. Search for "FCP_H_APPMANAGE_ENABLEPKG_SA" in bugreport log file | J30: After step 1, 7.1 Value of "ENABLEPKG" should be displayed as {"com.honda.ivi.systemupdate","com.honda.ivi.clockFaces","com.honda.ivi.am"} in ADB logs 7.2 "com.honda.ivi.telematicscontrolservice" value should not be displayed in "ENABLEPKG"
A31: 6 | B31: ー | C31: SR-180400-WFS-16 | D31: KPIT_VRNT_PJ02FEA10-504_8026 | E31: [SWT][KPIT_VRNT_PJ02FEA10-504_8026][Wi-Fi(Station)] | F31: To verify "Wi-Fi Hotspot" option is displayed on Home and All Apps screen when ICB is flashed with 30AJ2 variant code | G31: 1. IGN is ON and ICB is up and Ready 2. ICB is flashed with 30AJ2 variant code 3. ICB is started for the first time after SW flashing 4. Home screen is active | H31: 1. Observe "Wi-Fi Hotspot" | J31: After step 1, "Wi-Fi Hotspot" should be displayed on Home screen | K31: Wi-Fi(Station) | L31: Document Name: FCP_management_table_14-8155-s34-dev.xlsx Version : 215512 Section: Sheet/30AW/ENABLEPKG | M31: SWT_PJ, R1418 | N31: A14 | O31: 30AW | P31: KJ | Q31: 30AJ2 | R31: SWT1-2 | S31: Variant Test | T31: ー | U31: R1418 | V31: ー | W31: Draft | X31: Normal | Y31: JIRAUSER22518 | Z31: /A14/FCP Validation TCs/30AW/Wi-Fi(Station)/Variant Test | AB31: Shivani | AC31: Ankush | AD31: Variant is incorrect | AE31: Rework Needed | AM31: Hold | AP31: Niharika
B32: ー | H32: 2. Go to "アプリ一覧"(All Apps) | J32: After step 2, "Wi-Fi Hotspot" should be displayed on All Apps screen
A33: 7 | B33: ー | C33: ー | D33: KPIT_VRNT_PJ02FEA10-504_8027 | E33: [SWT][KPIT_VRNT_PJ02FEA10-504_8027][ー] | F33: To verify the value of "ENABLEPKG" is displayed as {"com.honda.ivi.dtv","com.honda.ivi.dtvservice","com.honda.ivi.etc","com.honda.ivi.am","com.honda.ivi.amtraffic","com.honda.ivi.internavi","com.honda.ivi.systemupdate","com.honda.ivi.telematicscontrolservice","com.honda.ivi.clockFaces","com.honda.ivi.vmsmediatorservice","com.honda.ivi.mapssettings","com.honda.ivi.ambientlight", "com.honda.ivi.sfd", "com.honda.ivi.hvaccontrol","jp.co.micware.wifihotspotapp"} in ADB logs when ICB is flashed with 30AJ3 variant code | G33: 1. IGN is ON and ICB is up and Ready 2. ICB is flashed with 30AJ3 variant code 3. ICB is started for the first time after SW flashing 4. Home screen is active | H33: 1. Go to Settings -> Advanced Settings -> System -> About -> Click on Build Number on 5 times -> Enter developer option password -> Back -> Developer option -> Enable USB Debugging Mode and USB Mode Setting enable | K33: ー | L33: Document Name: FCP_management_table_14-8155-s34-dev.xlsx Version : 215512 Section: Sheet/30AW/ENABLEPKG | M33: SWT_PJ, R1418 | N33: A14 | O33: 30AW | P33: KJ | Q33: 30AJ3 | R33: SWT1-2 | S33: Variant Test | T33: ADB Cable | U33: R1418 | V33: ー | W33: Draft | X33: Normal | Y33: JIRAUSER22518 | Z33: /A14/FCP Validation TCs/30AWー/Variant Test | AB33: Shivani | AC33: Ankush | AD33: No review comment | AE33: Finalized | AM33: Hold | AP33: Niharika
H34: 2. Go to extracted adb folder and enter command prompt by entering "cmd" in adb folder's path
H35: 3. Enter "adb devices" and check under "List of devices attached"
H36: 4. Enter "adb bugreport"
H37: 5. Extract "bugreport" folder
H38: 6. Open "bugreport" log file
H39: 7. Search for "FCP_H_APPMANAGE_ENABLEPKG_SA" in bugreport log file | J39: After step 1, 7.1 Value of "ENABLEPKG" should be displayed as {"com.honda.ivi.dtv","com.honda.ivi.dtvservice","com.honda.ivi.etc","com.honda.ivi.am","com.honda.ivi.amtraffic","com.honda.ivi.internavi","com.honda.ivi.systemupdate","com.honda.ivi.telematicscontrolservice","com.honda.ivi.clockFaces","com.honda.ivi.vmsmediatorservice","com.honda.ivi.mapssettings","com.honda.ivi.ambientlight", "com.honda.ivi.sfd", "com.honda.ivi.hvaccontrol","jp.co.micware.wifihotspotapp"} in ADB logs

Sheet T20Y6
A1: Sr. No. | B1: SCREEN_ID | C1: REQUIREMENT_ID | D1: KPIT_TC_ID | E1: Name | F1: Objective | G1: Precondition | H1: Test Script (Step-by-Step) - Step | I1: Test Script (Step-by-Step) - Test Data | J1: Test Script (Step-by-Step) - Expected Result | K1: FEATURE_1 | L1: REFERENCE_DOC | M1: Labels | N1: ANDROID_VER | O1: VEHICLE_MODEL | P1: REGION | Q1: VARIANT_CODE | R1: TEST_LEVEL | S1: TEST_TYPE | T1: HW_REQUIRED | U1: SRL_VERSION | V1: SUB_ID | W1: Status | X1: Priority | Y1: Owner | Z1: Folder | AA1: Vehicle model required for Execution e.g. 30AA Q | AB1: TC creator | AC1: L1 Review by | AD1: L1 Review Comments | AE1: TC Status | AF1: L2 Review by | AG1: L2 Review Comments | AH1: TC Status | AI1: L3 Review by | AJ1: L3 Review Comments | AK1: TC Status | AL1: Remarks | AM1: Execution feasibility Result (Pass/Fail) | AN1: Execution Model | AO1: Execution Region | AP1: Executed by
A2: 1 | B2: ー | C2: ー | D2: KPIT_VRNT_PJ02FEA10-504_8028 | E2: [SWT][KPIT_VRNT_PJ02FEA10-504_8028][IDS (Integrated Drive Mode System) ] | F2: To verify the value of "VEHICLE" is "{""}" in ADB logs when ICB is flashed with T20Y6 variant code | G2: 1. IGN is ON and ICB is up and Ready 2. ICB is flashed with T20Y6 variant code 3. ICB language is set to "English" (UK-English) 4. Home screen is active | H2: 1. Go to Settings -> Advanced Settings -> System -> About -> Click on Build Number on 5 times -> Enter developer option password -> Back -> Developer option -> Enable USB Debugging Mode and USB Mode Setting enable | K2: IDS (Integrated Drive Mode System) | L2: Document Name: FCP_management_table_14-8155-s34-dev.xlsx Version : 214345 Section: Sheet/T20T/VEHICLE | M2: SWT_PJ, R1418 | N2: A14 | O2: T20T | P2: KY | Q2: T20Y6 | R2: SWT1-2 | S2: Variant Test | T2: ADB Cable | U2: R1418 | V2: ー | W2: Draft | X2: Normal | Y2: JIRAUSER22518 | Z2: /A14/FCP Validation TCs/T20T/IDS (Integrated Drive Mode System)/Variant Test | AF2: Pravin | AG2: 3. Variant code is not correct in precondition2 | AH2: Rework Review | AM2: Pass | AP2: Niharika
H3: 2. Go to extracted adb folder and enter command prompt by entering "cmd" in adb folder's path
H4: 3. Enter "adb devices" and check under "List of devices attached"
H5: 4. Enter "adb bugreport"
H6: 5. Extract "bugreport" folder
H7: 6. Open "bugreport" log file
H8: 7. Search for FCP_H_INDIVIDUAL_VEHICLE_SA in bugreport log file | J8: After step 7, The value of "VEHICLE" should be "{""}" in ADB logs

Sheet T20Y7
A1: Sr. No. | B1: SCREEN_ID | C1: REQUIREMENT_ID | D1: KPIT_TC_ID | E1: Name | F1: Objective | G1: Precondition | H1: Test Script (Step-by-Step) - Step | I1: Test Script (Step-by-Step) - Test Data | J1: Test Script (Step-by-Step) - Expected Result | K1: FEATURE_1 | L1: REFERENCE_DOC | M1: Labels | N1: ANDROID_VER | O1: VEHICLE_MODEL | P1: REGION | Q1: VARIANT_CODE | R1: TEST_LEVEL | S1: TEST_TYPE | T1: HW_REQUIRED | U1: SRL_VERSION | V1: SUB_ID | W1: Status | X1: Priority | Y1: Owner | Z1: Folder | AA1: Vehicle model required for Execution e.g. 30AA Q | AB1: TC creator | AC1: L1 Review by | AD1: L1 Review Comments | AE1: TC Status | AF1: L2 Review by | AG1: L2 Review Comments | AH1: TC Status | AI1: L3 Review by | AJ1: L3 Review Comments | AK1: TC Status | AL1: Remarks | AM1: Execution feasibility Result (Pass/Fail) | AN1: Execution Model | AO1: Execution Region | AP1: Executed by
A2: 1 | B2: ー | C2: ー | D2: KPIT_VRNT_PJ02FEA10-504_8029 | E2: [SWT][KPIT_VRNT_PJ02FEA10-504_8029][IDS (Integrated Drive Mode System) ] | F2: To verify the value of "VEHICLE" is "{""}" in ADB logs when ICB is flashed with T20Y7 variant code | G2: 1. IGN is ON and ICB is up and Ready 2. ICB is flashed with T20Y7 variant code 3. ICB language is set to "English" (UK-English) 4. Home screen is active | H2: 1. Go to Settings -> Advanced Settings -> System -> About -> Click on Build Number on 5 times -> Enter developer option password -> Back -> Developer option -> Enable USB Debugging Mode and USB Mode Setting enable | K2: IDS (Integrated Drive Mode System) | L2: Document Name: FCP_management_table_14-8155-s34-dev.xlsx Version : 214345 Section: Sheet/T20T/VEHICLE | M2: SWT_PJ, R1418 | N2: A14 | O2: T20T | P2: KY | Q2: T20Y7 | R2: SWT1-2 | S2: Variant Test | T2: ADB Cable | U2: R1418 | V2: ー | W2: Draft | X2: Normal | Y2: JIRAUSER22518 | Z2: /A14/FCP Validation TCs/T20T/IDS (Integrated Drive Mode System)/Variant Test | AB2: Shivani | AC2: Ankush | AD2: No Review comment | AE2: Finalized | AF2: Pravin | AG2: 3. Variant code is not correct in precondition2 | AH2: Rework Review | AM2: Pass | AP2: Niharika
H3: 2. Go to extracted adb folder and enter command prompt by entering "cmd" in adb folder's path
H4: 3. Enter "adb devices" and check under "List of devices attached"
H5: 4. Enter "adb bugreport"
H6: 5. Extract "bugreport" folder
H7: 6. Open "bugreport" log file
H8: 7. Search for FCP_H_INDIVIDUAL_VEHICLE_SA in bugreport log file | J8: After step 7, The value of "VEHICLE" should be "{""}" in ADB logs

Sheet T20Y8
A1: Sr. No. | B1: SCREEN_ID | C1: REQUIREMENT_ID | D1: KPIT_TC_ID | E1: Name | F1: Objective | G1: Precondition | H1: Test Script (Step-by-Step) - Step | I1: Test Script (Step-by-Step) - Test Data | J1: Test Script (Step-by-Step) - Expected Result | K1: FEATURE_1 | L1: REFERENCE_DOC | M1: Labels | N1: ANDROID_VER | O1: VEHICLE_MODEL | P1: REGION | Q1: VARIANT_CODE | R1: TEST_LEVEL | S1: TEST_TYPE | T1: HW_REQUIRED | U1: SRL_VERSION | V1: SUB_ID | W1: Status | X1: Priority | Y1: Owner | Z1: Folder | AA1: Vehicle model required for Execution e.g. 30AA Q | AB1: TC creator | AC1: L1 Review by | AD1: L1 Review Comments | AE1: TC Status | AF1: L2 Review by | AG1: L2 Review Comments | AH1: TC Status | AI1: L3 Review by | AJ1: L3 Review Comments | AK1: TC Status | AL1: Remarks | AM1: Execution feasibility Result (Pass/Fail) | AN1: Execution Model | AO1: Execution Region | AP1: Executed by
A2: 1 | B2: ー | C2: SR-130100-IDS-12 | D2: KPIT_VRNT_PJ02FEA10-504_8030 | E2: [SWT][KPIT_VRNT_PJ02FEA10-504_8030][IDS (Integrated Drive Mode System) ] | F2: To verify "INDIVIDUAL Settings" is not displayed on Vehicle customization list screen while ICB is flashed with T20Y8 variant code | G2: 1. IGN is ON and ICB is up and Ready 2. ICB is flashed with T20Y8 variant code 3. ICB language is set to "English" (UK-English) 4. CANTOOL A1 is connected to ICB 5. Vehicle Settings Simulator is running on PC 6. Below BCAN Signal values are set in Vehicle Settings CAN simulator to enable options in Vehicle Customization screen C_MAINT_RESULT - 1: Successful reset C_MAINT_INFO - 1: US Smart Maintenance C_MAINT_OIL_LIFE - 1: 100% C_MAINT_DATA - 1 C_MAINT_UNIT - 1: km C_EW_MAINT - 1: Notice established C_MAINT_DATE_UNIT - 1: weeks C_NGST_CONNECTED - 0 : Other than diagnostic status 7. Home Screen is active | H2: 1. Go to "Vehicle Settings" | J2: After step 1, "INDIVIDUAL Settings" should not be displayed | K2: IDS (Integrated Drive Mode System) | L2: Document Name: FCP_management_table_14-8155-s34-dev.xlsx Version : 214345 Section: Sheet/T20T/VEHICLE | M2: SWT_PJ, R1418 | N2: A14 | O2: T20T | P2: KY | Q2: T20Y8 | R2: SWT1-2 | S2: Variant Test | T2: CANTOOL A1 | U2: R1418 | V2: ー | W2: Draft | X2: Normal | Y2: JIRAUSER22518 | Z2: /A14/FCP Validation TCs/T20T/IDS (Integrated Drive Mode System)/Variant Test | AB2: Shivani | AC2: Ankush | AD2: No review comments | AE2: Finalized | AF2: Pravin | AG2: 3. Variant code is not correct in precondition2 | AH2: Rework Review | AM2: Pass(No entries exit is dispalyed) | AP2: Niharika

Sheet T60T-Honda jira
A1: Sr. No. | B1: SCREEN_ID | C1: REQUIREMENT_ID | D1: KPIT_TC_ID | E1: Name | F1: Objective | G1: Precondition | H1: Test Script (Step-by-Step) - Step | I1: Test Script (Step-by-Step) - Test Data | J1: Test Script (Step-by-Step) - Expected Result | K1: FEATURE_1 | L1: REFERENCE_DOC | M1: Labels | N1: ANDROID_VER | O1: VEHICLE_MODEL | P1: REGION | Q1: VARIANT_CODE | R1: TEST_LEVEL | S1: TEST_TYPE | T1: HW_REQUIRED | U1: SRL_VERSION | V1: SUB_ID | W1: Status | X1: Priority | Y1: Owner | Z1: Folder | AA1: Vehicle model required for Execution e.g. 30AA Q | AB1: TC Status | AC1: L1 Review by | AD1: L1 Review on | AE1: L1 Review Comments | AF1: L1 Rework Review by | AG1: L1 Rework Review comments | AH1: Remarks | AI1: Execution feasibility Result (Pass/Fail) | AJ1: Execution Model | AK1: Execution Region | AL1: Executed by
A2: 1 | B2: ー | C2: SR-200200-DealerDiag-92 | D2: - | E2: - | F2: To verify the value of "8A050-T60-JA10" is displayed for Software No.(Soc) and "8A020-T60-JA10" is displayed for Software No.(Soc REG) on "バージョン情報 " (Version Detail Information) screen when ICB is flashed with T60J1 variant code | G2: 1. IGN is ON and ICB is up and Ready 2. ICB is flashed with T60J1 variant code 3. Detail Information & Setting screen is active (Press HOME + SEEK Down + Audio Power keys simultaneously for 5 seconds -> Detail Information & Setting) | H2: 1. Select "バージョン情報 " (Version Detail Information) | J2: After step 1, "8A050-T60-JA10" is displayed for Software No.(Soc) and "8A020-T60-JA10" is displayed for Software No.(Soc REG) on "バージョン情報 " (Version Detail Information) screen | K2: Dealer Diag | L2: Document Name: FCP_management_table_14-8155-s34-dev.xlsx Version : 215345 Section: Sheet/T60T/SOC_SWPN | M2: SWT_PJ, R1418 | N2: A14 | O2: T60T | P2: KJ | Q2: T60J1 | R2: SWT1-2 | S2: Variant Test | T2: ー | U2: R1418 | V2: ー | W2: Draft | X2: Normal | Y2: JIRAUSER22518 | Z2: /A14/FCP Validation TCs/T60T/Dealer Diag/Variant Test | AI2: Pass | AL2: Niharika
A3: 2 | B3: ー | C3: SR-200200-DealerDiag-92 | D3: - | E3: - | F3: To verify the value of "8A050-T60-YQ10" is displayed for Software No.(Soc) on "Version Detail Information" screen when ICB is flashed with T60Y1 variant code | G3: 1. IGN is ON and ICB is up and Ready 2. ICB is flashed with T60Y1 variant code 3. ICB language is set to "English" (UK-English) 4. Detail Information & Setting screen is active (Press HOME + SEEK Down + Audio Power keys simultaneously for 5 seconds -> Detail Information & Setting) | H3: 1. Select "Version" | J3: After step 1, "8A050-T60-YQ10" should be displayed for Software No.(Soc) on "Version Detail Information" screen | K3: Dealer Diag | L3: Document Name: FCP_management_table_14-8155-s34-dev.xlsx Version : 215345 Section: Sheet/T60T/SOC_SWPN | M3: SWT_PJ, R1418 | N3: A14 | O3: T60T | P3: KY | Q3: T60Y1 | R3: SWT1-2 | S3: Variant Test | T3: ー | U3: R1418 | V3: ー | W3: Draft | X3: Normal | Y3: JIRAUSER22518 | Z3: /A14/FCP Validation TCs/T60T/Dealer Diag/Variant Test | AI3: Pass | AL3: Niharika
A4: 3 | B4: ー | C4: SR-200200-DealerDiag-92 | D4: - | E4: - | F4: To verify the value of "8A050-T60-YB10" is displayed for Software No.(Soc) on "Version Detail Information" screen when ICB is flashed with T60Y2 variant code | G4: 1. IGN is ON and ICB is up and Ready 2. ICB is flashed with T60Y2 variant code 3. ICB language is set to "English" (UK-English) 4. Detail Information & Setting screen is active (Press HOME + SEEK Down + Audio Power keys simultaneously for 5 seconds -> Detail Information & Setting) | H4: 1. Select "Version" | J4: After step 1, "8A050-T60-YB10" should be displayed for Software No.(Soc) on "Version Detail Information" screen | K4: Dealer Diag | L4: Document Name: FCP_management_table_14-8155-s34-dev.xlsx Version : 215345 Section: Sheet/T60T/SOC_SWPN | M4: SWT_PJ, R1418 | N4: A14 | O4: T60T | P4: KY | Q4: T60Y2 | R4: SWT1-2 | S4: Variant Test | T4: ー | U4: R1418 | V4: ー | W4: Draft | X4: Normal | Y4: JIRAUSER22518 | Z4: /A14/FCP Validation TCs/T60T/Dealer Diag/Variant Test | AI4: Pass | AL4: Niharika
A5: 4 | B5: ー | C5: SR-200200-DealerDiag-92 | D5: - | E5: - | F5: To verify the value of "8A050-T60-FA10" is displayed for Software No.(Soc) and "8A020-T60-FA10" is displayed for Software No.(Soc REG) on Detailed version display screen when ICB is flashed with T60F0 variant code | G5: 1. IGN is ON and ICB is up and Ready 2. ICB is flashed with T60F0 variant code 3. ICB language is set to "English" (US-English) 4. Detail Information & Setting screen is active (Press HOME + SEEK Down + Audio Power keys simultaneously for 5 seconds -> Detail Information & Setting) | H5: 1. Select "Version" | J5: After step 1, "8A050-T60-FA10" should be displayed for Software No.(Soc) and "8A020-T60-FA10" should be displayed for Software No.(Soc REG) on Detailed version display screen | K5: Dealer Diag | L5: Document Name: FCP_management_table_14-8155-s34-dev.xlsx Version : 215345 Section: Sheet/T60T/SOC_SWPN | M5: SWT_PJ, R1418 | N5: A14 | O5: T60T | P5: FO | Q5: T60F0 | R5: SWT1-2 | S5: Variant Test | T5: ー | U5: R1418 | V5: ー | W5: Draft | X5: Normal | Y5: JIRAUSER22518 | Z5: /A14/FCP Validation TCs/T60T/Dealer Diag/Variant Test | AI5: PAss | AL5: Niharika
